<?xml version="1.0"?> 
<robot name="PuzzleBot"> 
    <!-- Dummy link to fix robot chassis --> 
    <link name="base_link"> 
        <pose>0 0 0 0 0 0</pose> 
    </link> 
 
    <joint name="base_link_to_chassis" type="fixed"> 
        <parent link="base_link"/> 
        <child link="chassis"/> 
    </joint> 
 
    <link name="chassis"> 
        <visual> 
            <origin rpy="${3.1416/2} 0.0 ${3.1416/2}" xyz="0 0 0.0"/> 
            <geometry> 
                <mesh filename="file://$(find puzzlebot_rviz_ch1)/meshes/MCR2_1000_13_Chassis.stl"/> 
            </geometry> 
            <material name="white"> 
                <color rgba="1 1 1 1"/> 
            </material> 
        </visual> 
    </link> 
    
    <!-- JOINTS  -->  
    <joint name="base_to_right_w" type="continuous"> 
        <parent link="base_link" /> 
        <child link="right_wheel" /> 
        <origin xyz="0.05 -0.09 0.0" /> 
        <axis xyz="0 1 0" rpy="0 0 0" /> 
    </joint> 
 
    <joint name="base_to_left_w" type="continuous"> 
        <parent link="base_link" /> 
        <child link="left_wheel" /> 
        <origin xyz="0.05 0.09 0" /> 
        <axis xyz="0 1 0" rpy="0 0 0" /> 
    </joint> 
 
 
    <!--RIGHT WHEEL --> 
    <link name="right_wheel"> 
        <visual> 
        <!--pi=3.14159265     pi/2= 1.57079632--> 
        <origin xyz="0 0 0" rpy="-1.57079632 0 0" /> 
        <geometry> 
            <!-- with mesh--> 
            <mesh filename="file://$(find puzzlebot_rviz_ch1)/meshes/MCR2_1000_1_1_Wheel_Coupler_2.stl"/> 
        </geometry> 
        </visual>           
    </link> 
     
    <!--LEFT WHEEL --> 
    <link name="left_wheel"> 
        <visual> 
        <!--pi=3.14159265     pi/2= 1.57079632--> 
        <origin xyz="0 0 0" rpy="1.57079632 0 0" /> 
        <geometry> 
            <!-- with mesh--> 
            <mesh filename="file://$(find puzzlebot_rviz_ch1)/meshes/MCR2_1000_1_1_Wheel_Coupler_2.stl"/> 
        </geometry> 
        </visual>           
    </link> 
</robot> 